<mujoco model="T1">
  <compiler angle="radian" meshdir="meshes" autolimits="true"/>

  <option integrator="implicitfast"/>


  <asset>
    <material name="light_gray" rgba="0.76 0.76 0.76 1"/>
    <material name="medium_gray" rgba="0.4 0.4 0.4 1"/>

    <!-- Head meshes -->
    <mesh name="H1" file="H1.STL"/>
    <mesh name="H2" file="H2.STL"/>

    <!-- Arm meshes -->
    <mesh name="AL1" file="AL1.STL"/>
    <mesh name="AL2" file="AL2.STL"/>
    <mesh name="AL3" file="AL3.STL"/>
    <mesh name="left_hand_link" file="left_hand_link.STL"/>
    <mesh name="AR1" file="AR1.STL"/>
    <mesh name="AR2" file="AR2.STL"/>
    <mesh name="AR3" file="AR3.STL"/>
    <mesh name="right_hand_link" file="right_hand_link.STL"/>

    <!-- Torso meshes -->
    <mesh name="Trunk" file="Trunk.STL"/>
    <mesh name="Waist" file="Waist.STL"/>

    <!-- Leg meshes -->
    <mesh name="Hip_Pitch_Left" file="Hip_Pitch_Left.STL"/>
    <mesh name="Hip_Roll_Left" file="Hip_Roll_Left.STL"/>
    <mesh name="Hip_Yaw_Left" file="Hip_Yaw_Left.STL"/>
    <mesh name="Shank_Left" file="Shank_Left.STL"/>
    <mesh name="Ankle_Cross_Left" file="Ankle_Cross_Left.STL"/>
    <mesh name="left_foot_link" file="left_foot_link.STL"/>
    <mesh name="Hip_Pitch_Right" file="Hip_Pitch_Right.STL"/>
    <mesh name="Hip_Roll_Right" file="Hip_Roll_Right.STL"/>
    <mesh name="Hip_Yaw_Right" file="Hip_Yaw_Right.STL"/>
    <mesh name="Shank_Right" file="Shank_Right.STL"/>
    <mesh name="Ankle_Cross_Right" file="Ankle_Cross_Right.STL"/>
    <mesh name="right_foot_link" file="right_foot_link.STL"/>
  </asset>

  <default>
    <default class="t1">
      <geom condim="1" contype="0" conaffinity="0" material="medium_gray"/>
      <site rgba="1 0 0 1" size="0.01" group="5"/>
      <joint/>

      <default class="visual">
        <geom type="mesh" contype="0" conaffinity="0" group="2"/>
      </default>

      <default class="collision">
        <geom group="3" contype="1" conaffinity="1"/>
      </default>

      <!-- Joint type classes (axis + range only, no passive dynamics) -->
      <default class="head_yaw">
        <joint axis="0 0 1" range="-1.57 1.57"/>
      </default>
      <default class="head_pitch">
        <joint axis="0 1 0" range="-0.35 1.22"/>
      </default>
      <default class="shoulder_pitch">
        <joint axis="0 1 0" range="-3.31 1.22"/>
      </default>
      <default class="shoulder_roll">
        <joint axis="1 0 0"/>
      </default>
      <default class="elbow_pitch">
        <joint axis="0 1 0" range="-2.27 2.27"/>
      </default>
      <default class="elbow_yaw">
        <joint axis="0 0 1"/>
      </default>
      <default class="waist">
        <joint axis="0 0 1" range="-1.57 1.57"/>
      </default>
      <default class="hip_pitch">
        <joint axis="0 1 0" range="-1.8 1.57"/>
      </default>
      <default class="hip_roll">
        <joint axis="1 0 0"/>
      </default>
      <default class="hip_yaw">
        <joint axis="0 0 1" range="-1 1"/>
      </default>
      <default class="knee">
        <joint axis="0 1 0" range="0 2.34"/>
      </default>
      <default class="ankle_pitch">
        <joint axis="0 1 0" range="-0.87 0.35"/>
      </default>
      <default class="ankle_roll">
        <joint axis="1 0 0" range="-0.44 0.44"/>
      </default>

      <position kp="75" kv="5"/>
    </default>
  </default>

  <worldbody>
    <light pos="1 0 3.5" dir="0 0 -1" directional="true"/>
    <body name="Trunk" pos="0 0 .7" childclass="t1">
      <freejoint name="floating_base_joint"/>
      <inertial pos="0.0551365 -1.42058e-06 0.105062" quat="0.99996 1.40561e-05 -0.00899532 -1.39249e-05" mass="11.7" diaginertia="0.0915404 0.0767787 0.0556055"/>
      <site name='imu'/>
      <site name='root_site'/>
      <geom class="visual" material="light_gray" mesh="Trunk"/>
      <geom name="Trunk" class="collision" type="mesh" mesh="Trunk"/>

      <!-- Head -->
      <body name="H1" pos="0.0625 0 0.243">
        <inertial pos="-0.000508 -0.001403 0.057432" quat="0.763881 -0.0132172 0.00173419 0.645219" mass="0.44391" diaginertia="0.000241549 0.00022351 0.000149941"/>
        <joint name="AAHead_yaw" actuatorfrcrange="-7 7" class="head_yaw"/>
        <geom class="visual" mesh="H1"/>
        <geom name="H1" class="collision" type="mesh" mesh="H1"/>

        <body name="H2" pos="0 0 0.06185">
          <inertial pos="0.007802 0.001262 0.098631" quat="0.988453 0.106172 -0.0745686 -0.0782786" mass="0.631019" diaginertia="0.00203553 0.00192467 0.00172381"/>
          <joint name="Head_pitch" actuatorfrcrange="-7 7" class="head_pitch"/>
          <geom class="visual" mesh="H2"/>
          <geom name="H2" class="collision" type="mesh" mesh="H2"/>
        </body>
      </body>

      <!-- Left arm -->
      <body name="AL1" pos="0.0575 0.1063 0.219" quat="1 0 0.000440565 0">
        <inertial pos="-0.000677 0.044974 0" quat="0.50423 0.495734 -0.50423 0.495734" mass="0.53" diaginertia="0.001367 0.00129329 0.000292711"/>
        <joint name="Left_Shoulder_Pitch" actuatorfrcrange="-18 18" class="shoulder_pitch"/>
        <geom class="visual" material="light_gray" mesh="AL1"/>
        <geom name="AL1" class="collision" type="mesh" mesh="AL1"/>

        <body name="AL2" pos="0 0.047 0">
          <inertial pos="0.003862 0.037976 0" quat="0.487991 0.511727 -0.487991 0.511727" mass="0.16" diaginertia="0.000401 0.00034538 0.00017662"/>
          <joint name="Left_Shoulder_Roll" range="-1.74 1.57" actuatorfrcrange="-18 18" class="shoulder_roll"/>
          <geom class="visual" mesh="AL2"/>
          <geom name="AL2" class="collision" type="mesh" mesh="AL2"/>

          <body name="AL3" pos="0.00025 0.0605 0">
            <inertial pos="0 0.085353 -9.9e-05" quat="0.70641 0.707803 0 0" mass="1.02" diaginertia="0.012869 0.012798 0.000620953"/>
            <joint name="Left_Elbow_Pitch" actuatorfrcrange="-18 18" class="elbow_pitch"/>
            <geom class="visual" mesh="AL3"/>
            <geom name="AL3" class="collision" type="mesh" mesh="AL3"/>

            <body name="left_hand_link" pos="0 0.1471 0">
              <inertial pos="-0.000108 0.109573 0.000591" quat="0.707866 0.706347 -5.22939e-05 -0.000214913" mass="0.327214" diaginertia="0.008159 0.00813104 0.000214962"/>
              <joint name="Left_Elbow_Yaw" range="-2.44 0" actuatorfrcrange="-18 18" class="elbow_yaw"/>
              <geom class="visual" mesh="left_hand_link"/>
              <geom name="left_hand_link" class="collision" type="mesh" mesh="left_hand_link"/>

              <body name="left_hand_sphere_link" pos="0.0 0.2 0.0">
                <inertial pos="0 0 0" mass="0.001" diaginertia="1e-7 1e-7 1e-7"/>
                <geom name="left_hand_sphere_link" type="sphere" size="0.005" rgba="0.2 0.2 0.2 1"/>
              </body>
            </body>
          </body>
        </body>
      </body>

      <!-- Right arm -->
      <body name="AR1" pos="0.0575 -0.1063 0.219" quat="1 0 0.000440565 0">
        <inertial pos="-0.000677 -0.044974 0" quat="0.50423 0.495734 -0.50423 0.495734" mass="0.53" diaginertia="0.001367 0.00129329 0.000292711"/>
        <joint name="Right_Shoulder_Pitch" actuatorfrcrange="-18 18" class="shoulder_pitch"/>
        <geom class="visual" material="light_gray" mesh="AR1"/>
        <geom name="AR1" class="collision" type="mesh" mesh="AR1"/>

        <body name="AR2" pos="0 -0.047 0">
          <inertial pos="0.003862 -0.037976 0" quat="0.511727 0.487991 -0.511727 0.487991" mass="0.16" diaginertia="0.000401 0.00034538 0.00017662"/>
          <joint name="Right_Shoulder_Roll" range="-1.57 1.74" actuatorfrcrange="-18 18" class="shoulder_roll"/>
          <geom class="visual" mesh="AR2"/>
          <geom name="AR2" class="collision" type="mesh" mesh="AR2"/>

          <body name="AR3" pos="0.00025 -0.0605 0">
            <inertial pos="0 -0.085353 -9.9e-05" quat="0.707803 0.70641 0 0" mass="1.02" diaginertia="0.012869 0.012798 0.000620953"/>
            <joint name="Right_Elbow_Pitch" actuatorfrcrange="-18 18" class="elbow_pitch"/>
            <geom class="visual" mesh="AR3"/>
            <geom name="AR3" class="collision" type="mesh" mesh="AR3"/>

            <body name="right_hand_link" pos="0 -0.1471 0">
              <inertial pos="-0.000108 -0.109573 0.000591" quat="0.706347 0.707866 0.000214913 5.22939e-05" mass="0.327214" diaginertia="0.008159 0.00813104 0.000214962"/>
              <joint name="Right_Elbow_Yaw" range="0 2.44" actuatorfrcrange="-18 18" class="elbow_yaw"/>
              <geom class="visual" mesh="right_hand_link"/>
              <geom name="right_hand_link" class="collision" type="mesh" mesh="right_hand_link"/>

              <body name="right_hand_sphere_link" pos="0.0 -0.2 0.0">
                <inertial pos="0 0 0" mass="0.001" diaginertia="1e-7 1e-7 1e-7"/>
                <geom name="right_hand_sphere_link" type="sphere" size="0.005" rgba="0.2 0.2 0.2 1"/>
              </body>
            </body>
          </body>
        </body>
      </body>

      <!-- Waist and legs -->
      <body name="Waist" pos="0.0625 0 -0.1155">
        <inertial pos="0.002284 3e-06 0.007301" quat="0.983649 0.000360386 -0.180076 0.00269791" mass="2.581" diaginertia="0.00536742 0.005299 0.00474258"/>
        <joint name="Waist" actuatorfrcrange="-30 30" class="waist"/>
        <geom class="visual" mesh="Waist"/>
        <geom name="Waist" class="collision" type="mesh" mesh="Waist"/>

        <!-- Left leg -->
        <body name="Hip_Pitch_Left" pos="0 0.106 0">
          <inertial pos="0.000534 -0.007296 -0.018083" quat="0.975141 0.2211 0.0145808 0.0017406" mass="1.021" diaginertia="0.00180547 0.00145926 0.00125327"/>
          <joint name="Left_Hip_Pitch" actuatorfrcrange="-45 45" class="hip_pitch"/>
          <geom class="visual" material="light_gray" mesh="Hip_Pitch_Left"/>
          <geom name="Hip_Pitch_Left" class="collision" type="mesh" mesh="Hip_Pitch_Left"/>

          <body name="Hip_Roll_Left" pos="0 0 -0.02">
            <inertial pos="0.001101 2.4e-05 -0.05375" quat="0.707081 -0.00599604 -0.00599604 0.707081" mass="0.385" diaginertia="0.001743 0.00151729 0.000514712"/>
            <joint name="Left_Hip_Roll" range="-0.2 1.57" actuatorfrcrange="-30 30" class="hip_roll"/>
            <geom class="visual" mesh="Hip_Roll_Left"/>
            <geom name="Hip_Roll_Left" class="collision" type="mesh" mesh="Hip_Roll_Left"/>

            <body name="Hip_Yaw_Left" pos="0 0 -0.081854">
              <inertial pos="-0.007233 0.000206 -0.089184" quat="0.696808 -0.033953 -0.0315708 0.715758" mass="2.166" diaginertia="0.0257334 0.0253024 0.00259215"/>
              <joint name="Left_Hip_Yaw" actuatorfrcrange="-30 30" class="hip_yaw"/>
              <geom class="visual" mesh="Hip_Yaw_Left"/>
              <geom name="Hip_Yaw_Left" class="collision" type="mesh" mesh="Hip_Yaw_Left"/>

              <body name="Shank_Left" pos="-0.014 0 -0.134">
                <inertial pos="-0.006012 0.000259 -0.124318" quat="0.997573 0.00144024 -0.023949 0.0653706" mass="1.73" diaginertia="0.0346951 0.0345375 0.00185844"/>
                <joint name="Left_Knee_Pitch" actuatorfrcrange="-60 60" class="knee"/>
                <geom class="visual" mesh="Shank_Left"/>
                <geom name="Shank_Left" class="collision" type="mesh" mesh="Shank_Left"/>

                <body name="Ankle_Cross_Left" pos="0 0 -0.28">
                  <inertial pos="-0.003722 0 -0.007981" quat="0.443136 0.551027 0.551027 0.443136" mass="0.073" diaginertia="2.9e-05 2.56589e-05 1.13411e-05"/>
                  <joint name="Left_Ankle_Pitch" actuatorfrcrange="-20 20" class="ankle_pitch"/>
                  <geom class="visual" mesh="Ankle_Cross_Left"/>
                  <geom name="Ankle_Cross_Left" class="collision" type="mesh" mesh="Ankle_Cross_Left"/>

                  <body name="left_foot_link" pos="0 0.00025 -0.012">
                    <inertial pos="-0.000249 0 -0.00914" quat="0 0.651138 0 0.75896" mass="0.685" diaginertia="0.00269361 0.002385 0.00171539"/>
                    <joint name="Left_Ankle_Roll" actuatorfrcrange="-15 15" class="ankle_roll"/>
                    <site name="left_foot" pos="0 0 -0.02"/>
                    <geom class="visual" mesh="left_foot_link"/>
                    <geom name="left_foot_link" class="collision" type="mesh" mesh="left_foot_link"/>

                    <!-- Foot contact spheres -->
                    <body name="left_foot_sphere_1_link" pos="-0.1 0.025 -0.03">
                      <inertial pos="0 0 0" mass="0.001" diaginertia="1e-7 1e-7 1e-7"/>
                      <geom name="left_foot_sphere_1_link" type="sphere" size="0.005" rgba="0.2 0.2 0.2 1"/>
                    </body>
                    <body name="left_foot_sphere_2_link" pos="-0.1 -0.025 -0.03">
                      <inertial pos="0 0 0" mass="0.001" diaginertia="1e-7 1e-7 1e-7"/>
                      <geom name="left_foot_sphere_2_link" type="sphere" size="0.005" rgba="0.2 0.2 0.2 1"/>
                    </body>
                    <body name="left_foot_sphere_3_link" pos="0.11 0.03 -0.03">
                      <inertial pos="0 0 0" mass="0.001" diaginertia="1e-7 1e-7 1e-7"/>
                      <geom name="left_foot_sphere_3_link" type="sphere" size="0.005" rgba="0.2 0.2 0.2 1"/>
                    </body>
                    <body name="left_foot_sphere_4_link" pos="0.11 -0.03 -0.03">
                      <inertial pos="0 0 0" mass="0.001" diaginertia="1e-7 1e-7 1e-7"/>
                      <geom name="left_foot_sphere_4_link" type="sphere" size="0.005" rgba="0.2 0.2 0.2 1"/>
                    </body>
                    <body name="left_foot_sphere_5_link" pos="0.12 0 -0.03">
                      <inertial pos="0 0 0" mass="0.001" diaginertia="1e-7 1e-7 1e-7"/>
                      <geom name="left_foot_sphere_5_link" type="sphere" size="0.005" rgba="0.2 0.2 0.2 1"/>
                    </body>
                    <!-- Side contact spheres (mid-height, for ball kicking) -->
                    <body name="left_foot_sphere_6_link" pos="0.06 0.035 -0.01">
                      <inertial pos="0 0 0" mass="0.001" diaginertia="1e-7 1e-7 1e-7"/>
                      <geom name="left_foot_sphere_6_link" type="sphere" size="0.005" rgba="0.8 0.2 0.2 1"/>
                    </body>
                    <body name="left_foot_sphere_7_link" pos="0.06 -0.035 -0.01">
                      <inertial pos="0 0 0" mass="0.001" diaginertia="1e-7 1e-7 1e-7"/>
                      <geom name="left_foot_sphere_7_link" type="sphere" size="0.005" rgba="0.8 0.2 0.2 1"/>
                    </body>
                    <body name="left_foot_sphere_8_link" pos="-0.02 0.035 -0.01">
                      <inertial pos="0 0 0" mass="0.001" diaginertia="1e-7 1e-7 1e-7"/>
                      <geom name="left_foot_sphere_8_link" type="sphere" size="0.005" rgba="0.8 0.2 0.2 1"/>
                    </body>
                    <body name="left_foot_sphere_9_link" pos="-0.02 -0.035 -0.01">
                      <inertial pos="0 0 0" mass="0.001" diaginertia="1e-7 1e-7 1e-7"/>
                      <geom name="left_foot_sphere_9_link" type="sphere" size="0.005" rgba="0.8 0.2 0.2 1"/>
                    </body>
                    <body name="left_foot_sphere_10_link" pos="0.13 0 -0.01">
                      <inertial pos="0 0 0" mass="0.001" diaginertia="1e-7 1e-7 1e-7"/>
                      <geom name="left_foot_sphere_10_link" type="sphere" size="0.005" rgba="0.8 0.2 0.2 1"/>
                    </body>
                  </body>
                </body>
              </body>
            </body>
          </body>
        </body>

        <!-- Right leg -->
        <body name="Hip_Pitch_Right" pos="0 -0.106 0">
          <inertial pos="0.000534 0.007514 -0.018082" quat="0.973446 -0.228403 0.0147148 -0.00419349" mass="1.021" diaginertia="0.00180552 0.0014632 0.00124928"/>
          <joint name="Right_Hip_Pitch" actuatorfrcrange="-45 45" class="hip_pitch"/>
          <geom class="visual" material="light_gray" mesh="Hip_Pitch_Right"/>
          <geom name="Hip_Pitch_Right" class="collision" type="mesh" mesh="Hip_Pitch_Right"/>

          <body name="Hip_Roll_Right" pos="0 0 -0.02">
            <inertial pos="0.001099 2.4e-05 -0.053748" quat="0.707081 -0.00599604 -0.00599604 0.707081" mass="0.385" diaginertia="0.001743 0.00151729 0.000514712"/>
            <joint name="Right_Hip_Roll" range="-1.57 0.2" actuatorfrcrange="-30 30" class="hip_roll"/>
            <geom class="visual" mesh="Hip_Roll_Right"/>
            <geom name="Hip_Roll_Right" class="collision" type="mesh" mesh="Hip_Roll_Right"/>

            <body name="Hip_Yaw_Right" pos="0 0 -0.081854">
              <inertial pos="-0.007191 -0.000149 -0.08922" quat="0.714468 -0.0315638 -0.0336391 0.698146" mass="2.17" diaginertia="0.0257623 0.0253298 0.00259389"/>
              <joint name="Right_Hip_Yaw" actuatorfrcrange="-30 30" class="hip_yaw"/>
              <geom class="visual" mesh="Hip_Yaw_Right"/>
              <geom name="Hip_Yaw_Right" class="collision" type="mesh" mesh="Hip_Yaw_Right"/>

              <body name="Shank_Right" pos="-0.014 0 -0.134">
                <inertial pos="-0.005741 -0.000541 -0.122602" quat="0.99926 -0.000580963 -0.023461 -0.0304754" mass="1.79" diaginertia="0.0351717 0.0349574 0.00196589"/>
                <joint name="Right_Knee_Pitch" actuatorfrcrange="-60 60" class="knee"/>
                <geom class="visual" mesh="Shank_Right"/>
                <geom name="Shank_Right" class="collision" type="mesh" mesh="Shank_Right"/>

                <body name="Ankle_Cross_Right" pos="0 0 -0.28">
                  <inertial pos="-0.003722 0 -0.007981" quat="0.443136 0.551027 0.551027 0.443136" mass="0.073" diaginertia="2.9e-05 2.56589e-05 1.13411e-05"/>
                  <joint name="Right_Ankle_Pitch" actuatorfrcrange="-20 20" class="ankle_pitch"/>
                  <geom class="visual" mesh="Ankle_Cross_Right"/>
                  <geom name="Ankle_Cross_Right" class="collision" type="mesh" mesh="Ankle_Cross_Right"/>

                  <body name="right_foot_link" pos="0 -0.00025 -0.012">
                    <inertial pos="-0.000248 0 -0.00914" quat="0 0.651138 0 0.75896" mass="0.685" diaginertia="0.00269361 0.002385 0.00171539"/>
                    <joint name="Right_Ankle_Roll" actuatorfrcrange="-15 15" class="ankle_roll"/>
                    <site name="right_foot" pos="0 0 -0.02"/>
                    <geom class="visual" mesh="right_foot_link"/>
                    <geom name="right_foot_link" class="collision" type="mesh" mesh="right_foot_link"/>


                    <!-- Foot contact spheres -->
                    <body name="right_foot_sphere_1_link" pos="-0.1 0.025 -0.03">
                      <inertial pos="0 0 0" mass="0.001" diaginertia="1e-7 1e-7 1e-7"/>
                      <geom name="right_foot_sphere_1_link" type="sphere" size="0.005" rgba="0.2 0.2 0.2 1"/>
                    </body>
                    <body name="right_foot_sphere_2_link" pos="-0.1 -0.025 -0.03">
                      <inertial pos="0 0 0" mass="0.001" diaginertia="1e-7 1e-7 1e-7"/>
                      <geom name="right_foot_sphere_2_link" type="sphere" size="0.005" rgba="0.2 0.2 0.2 1"/>
                    </body>
                    <body name="right_foot_sphere_3_link" pos="0.11 0.03 -0.03">
                      <inertial pos="0 0 0" mass="0.001" diaginertia="1e-7 1e-7 1e-7"/>
                      <geom name="right_foot_sphere_3_link" type="sphere" size="0.005" rgba="0.2 0.2 0.2 1"/>
                    </body>
                    <body name="right_foot_sphere_4_link" pos="0.11 -0.03 -0.03">
                      <inertial pos="0 0 0" mass="0.001" diaginertia="1e-7 1e-7 1e-7"/>
                      <geom name="right_foot_sphere_4_link" type="sphere" size="0.005" rgba="0.2 0.2 0.2 1"/>
                    </body>
                    <body name="right_foot_sphere_5_link" pos="0.12 0 -0.03">
                      <inertial pos="0 0 0" mass="0.001" diaginertia="1e-7 1e-7 1e-7"/>
                      <geom name="right_foot_sphere_5_link" type="sphere" size="0.005" rgba="0.2 0.2 0.2 1"/>
                    </body>
                    <!-- Side contact spheres (mid-height, for ball kicking) -->
                    <body name="right_foot_sphere_6_link" pos="0.06 0.035 -0.01">
                      <inertial pos="0 0 0" mass="0.001" diaginertia="1e-7 1e-7 1e-7"/>
                      <geom name="right_foot_sphere_6_link" type="sphere" size="0.005" rgba="0.8 0.2 0.2 1"/>
                    </body>
                    <body name="right_foot_sphere_7_link" pos="0.06 -0.035 -0.01">
                      <inertial pos="0 0 0" mass="0.001" diaginertia="1e-7 1e-7 1e-7"/>
                      <geom name="right_foot_sphere_7_link" type="sphere" size="0.005" rgba="0.8 0.2 0.2 1"/>
                    </body>
                    <body name="right_foot_sphere_8_link" pos="-0.02 0.035 -0.01">
                      <inertial pos="0 0 0" mass="0.001" diaginertia="1e-7 1e-7 1e-7"/>
                      <geom name="right_foot_sphere_8_link" type="sphere" size="0.005" rgba="0.8 0.2 0.2 1"/>
                    </body>
                    <body name="right_foot_sphere_9_link" pos="-0.02 -0.035 -0.01">
                      <inertial pos="0 0 0" mass="0.001" diaginertia="1e-7 1e-7 1e-7"/>
                      <geom name="right_foot_sphere_9_link" type="sphere" size="0.005" rgba="0.8 0.2 0.2 1"/>
                    </body>
                    <body name="right_foot_sphere_10_link" pos="0.13 0 -0.01">
                      <inertial pos="0 0 0" mass="0.001" diaginertia="1e-7 1e-7 1e-7"/>
                      <geom name="right_foot_sphere_10_link" type="sphere" size="0.005" rgba="0.8 0.2 0.2 1"/>
                    </body>
                  </body>
                </body>
              </body>
            </body>
          </body>
        </body>
      </body>
    </body>
  </worldbody>

  <sensor>
    <gyro name="imu_ang_vel" site="imu"/>
    <velocimeter name="imu_lin_vel" site="imu"/>
    <accelerometer name="imu_lin_acc" site="imu"/>
    <framequat name="orientation" objtype="site" objname="imu"/>
    <subtreeangmom name="root_angmom" body="Trunk"/>
  </sensor>
</mujoco>
